Workbook

Sheet Read Me
A1: Lio ICP Prospect List
A3: What this is | B3: Named-buyer prospect list for Lio (lio.ai), sourced against the ICP reverse-engineered in the Lio knowledge base (file 10-events-and-icp.md). Built 2026-08-31 as part of Abir Khan's founders-associate application package.
A4: How it was sourced | B4: Apollo.io People & Organization Search with explicit firmographic/title filters per segment (filters documented in 13-icp-prospect-list.md), then per-person enrichment via Apollo People Match to reveal full names, work emails and LinkedIn URLs.
A5: Coverage vs totals | B5: The list holds 219 named contacts at 122 companies. Apollo reports 2,245 titled buyers / 1,933 companies matching the same filters in total - the list is the top slice (pages 1-2 per search), and the search filters are reusable to refill it.
A6: Cost transparency | B6: Enrichment consumed 219 Apollo lead credits (1 per contact). Searches are free. Team balance after the run is reported in 13-icp-prospect-list.md.
A7: Email quality | B7: 193 verified work emails, 5 extrapolated, 21 unavailable (Apollo email_status field, column I of Contacts).
A8: Tabs | B8: Exec Summary (numbers) / Contacts (all 219, one row each) / Companies (122) / Approach Playbook (per segment: buying center, message, channels, rooms, proof, timing).
A9: Legend | B9: No cells require filling in; this is a data deliverable. Yellow cells on Exec Summary are hardcoded Apollo-reported totals (source noted beside them); all other summary numbers are formulas over the Contacts/Companies tabs.
A10: Compliance note | B10: Contact data is Apollo-licensed B2B data pulled under the team's Apollo seat; use per your outbound/GDPR policy (legitimate-interest B2B outreach; include opt-outs in DACH sequences).

Sheet Exec Summary
A1: Lio ICP Prospect List - Executive Summary
A2: Sourced via Apollo 2026-08-31 - formulas count the Contacts tab; yellow cells are Apollo-reported database totals (source: pagination.total_entries per search)
A4: Segment | B4: Contacts on list | C4: Verified emails | D4: Any email | E4: Apollo total buyers | F4: Apollo total companies | G4: Companies on list
A5: DACH Industrial | B5: =COUNTIF(Contacts!$B:$B,A5) | C5: =COUNTIFS(Contacts!$B:$B,A5,Contacts!$I:$I,"verified") | D5: =COUNTIFS(Contacts!$B:$B,A5,Contacts!$H:$H,"<>") | E5: 851 | F5: 153 | G5: =COUNTIF(Companies!$B:$B,A5)
A6: Insurance & FS | B6: =COUNTIF(Contacts!$B:$B,A6) | C6: =COUNTIFS(Contacts!$B:$B,A6,Contacts!$I:$I,"verified") | D6: =COUNTIFS(Contacts!$B:$B,A6,Contacts!$H:$H,"<>") | E6: 156 | F6: 34 | G6: =COUNTIF(Companies!$B:$B,A6)
A7: US GBS & BPO Owners | B7: =COUNTIF(Contacts!$B:$B,A7) | C7: =COUNTIFS(Contacts!$B:$B,A7,Contacts!$I:$I,"verified") | D7: =COUNTIFS(Contacts!$B:$B,A7,Contacts!$H:$H,"<>") | E7: 895 | F7: 1665 | G7: =COUNTIF(Companies!$B:$B,A7)
A8: Utilities & Mobility | B8: =COUNTIF(Contacts!$B:$B,A8) | C8: =COUNTIFS(Contacts!$B:$B,A8,Contacts!$I:$I,"verified") | D8: =COUNTIFS(Contacts!$B:$B,A8,Contacts!$H:$H,"<>") | E8: 343 | F8: 81 | G8: =COUNTIF(Companies!$B:$B,A8)
A9: TOTAL | B9: =SUM(B5:B8) | C9: =SUM(C5:C8) | D9: =SUM(D5:D8) | E9: =SUM(E5:E8) | F9: =SUM(F5:F8) | G9: =SUM(G5:G8)
A11: Seniority mix (list) | D11: Email status (list)
A12: c_suite | B12: =COUNTIF(Contacts!$G:$G,A12) | D12: verified | E12: =COUNTIF(Contacts!$I:$I,D12)
A13: head | B13: =COUNTIF(Contacts!$G:$G,A13) | D13: extrapolated | E13: =COUNTIF(Contacts!$I:$I,D13)
A14: vp | B14: =COUNTIF(Contacts!$G:$G,A14) | D14: unavailable | E14: =COUNTIF(Contacts!$I:$I,D14)
A15: director | B15: =COUNTIF(Contacts!$G:$G,A15)
A17: Search filters per segment: documented in 13-icp-prospect-list.md (locations, employee ranges, revenue floors, NAICS codes, title lists). Re-run the same filters in Apollo to refill the list; ~2,000 more titled buyers remain unpulled.

Sheet Contacts
A1: # | B1: Segment | C1: Name | D1: Title | E1: Company | F1: Company domain | G1: Seniority | H1: Email | I1: Email status | J1: LinkedIn URL | K1: Location | L1: Company employees | M1: Company industry | N1: Apollo person ID
A2: 1 | B2: DACH Industrial | C2: Frank Arendt | D2: Chief Procurement Officer | E2: Barry Callebaut Group | F2: barry-callebaut.com | G2: c_suite | H2: frank_arendt@barry-callebaut.com | I2: verified | J2: http://www.linkedin.com/in/frank-arendt-geneva | K2: Zuerich, Switzerland | L2: 14000 | M2: food production | N2: 66f41063d0097300015aa080
A3: 2 | B3: DACH Industrial | C3: Christine Berg | D3: Chief Procurement Officer | E3: Beiersdorf | F3: beiersdorf.com | G3: c_suite | H3: christine.berg@beiersdorf.com | I3: verified | J3: http://www.linkedin.com/in/christine-berg-41925b26 | K3: Hamburg, Germany | L3: 22000 | M3: cosmetics | N3: 610955967b1bdb00018b2331
A4: 3 | B4: DACH Industrial | C4: Harry Bloechlinger | D4: Chief Procurement Officer | E4: Bühler Group | F4: buhlergroup.com | G4: c_suite | H4: harry.bloechlinger@buhlergroup.com | I4: verified | J4: http://www.linkedin.com/in/harry-bloechlinger | K4: Uzwil, Switzerland | L4: 13000 | M4: machinery | N4: 6764f829d1ec910001a18540
A5: 4 | B5: DACH Industrial | C5: Nicola Comiotto | D5: Chief Procurement Officer | E5: Clariant | F5: clariant.com | G5: c_suite | H5: nicola.comiotto@clariant.com | I5: verified | J5: http://www.linkedin.com/in/nicola-comiotto-3b58a5135 | K5: Basel, Switzerland | L5: 11000 | M5: chemicals | N5: 622ef3d583d3560001cadd7b
A6: 5 | B6: DACH Industrial | C6: Rene Schwalm | D6: Chief Procurement Officer | E6: Dürr Group | F6: durr-group.com | G6: c_suite | H6: rene.schwalm@durr.com | I6: verified | J6: http://www.linkedin.com/in/ren%c3%a9-schwalm-15b5bb136 | K6: Bietigheim-Bissingen, Germany | L6: 18000 | M6: machinery | N6: 5d45e329a3ae613e1bd50f00
A7: 6 | B7: DACH Industrial | C7: Patrick Frings | D7: Chief Procurement Officer / VP Global Procurement | E7: ENERCON | F7: enercon.com | G7: c_suite | H7: patrick.frings@enercon.de | I7: verified | J7: http://www.linkedin.com/in/patrick-frings76 | K7: Muenster, Germany | L7: 13000 | M7: civil engineering | N7: 60b5fb90796d56000177eeaa
A8: 7 | B8: DACH Industrial | C8: Zoe Ren | D8: Chief Procurement Officer | E8: Ferring Pharmaceuticals | F8: ferring.com | G8: c_suite | H8: zoe.ren@ferring.com | I8: verified | J8: http://www.linkedin.com/in/zoe-ren-4b26ba7 | K8: Lausanne, Switzerland | L8: 7000 | M8: pharmaceuticals | N8: 66f7b7885812e80001a4cdda
A9: 8 | B9: DACH Industrial | C9: Thomas-Garry Stiller | D9: Senior Vice President & Chief Procurement Officer | E9: HARTMANN GROUP | F9: hartmann.info | G9: c_suite | H9: thomas-garry.stiller@hartmann.info | I9: verified | J9: http://www.linkedin.com/in/thomas-garry-stiller-090b697 | K9: Ulm, Germany | L9: 11000 | M9: medical devices | N9: 60ffdb790ec80d0001419c7e
A10: 9 | B10: DACH Industrial | C10: Jochen Pfister | D10: Chief Procurement Officer | E10: HENSOLDT | F10: hensoldt.net | G10: c_suite | H10: jochen.pfister@hensoldt.net | I10: verified | J10: http://www.linkedin.com/in/jochen-pfister-38a65337 | K10: Germany | L10: 9400 | M10: defense & space | N10: 54a7e7a6746869730ab04457
A11: 10 | B11: DACH Industrial | C11: Mathan Durairaj | D11: Chief Procurement Officer | E11: Holcim | F11: holcim.com | G11: c_suite | H11: mathan.durairaj@lafargeholcim.com | I11: verified | J11: http://www.linkedin.com/in/mathan-durairaj-59156791 | K11: Thalwil, Switzerland | L11: 19000 | M11: construction | N11: 678c2af3f847860001bea839
A12: 11 | B12: DACH Industrial | C12: Stefan Thomas | D12: Chief Procurement Officer | E12: INNIO Group | F12: innio.com | G12: c_suite | H12: stefan.thomas@innio.com | I12: verified | J12: http://www.linkedin.com/in/stefan-thomas-198054a0 | K12: Austria | L12: 5300 | M12: machinery | N12: 60e80c79aa6963000147f7fa
A13: 12 | B13: DACH Industrial | C13: Samuel Cochon | D13: Chief Procurement Officer | E13: MANN+HUMMEL | F13: mann-hummel.com | G13: c_suite | H13: samuel.cochon@mann-hummel.com | I13: verified | J13: http://www.linkedin.com/in/samuel-cochon-a5623b16 | K13: Lausanne, Switzerland | L13: 22000 | M13: environmental services | N13: 6634791866173900075a4d32
A14: 13 | B14: DACH Industrial | C14: Johan Keerberg | D14: Chief Procurement Officer | E14: Migros Industrie | F14: migrosindustrie.ch | G14: c_suite | H14: johan.keerberg@migrosindustrie.ch | I14: verified | J14: http://www.linkedin.com/in/johan-keerberg-78737120 | K14: Zuerich, Switzerland | L14: 13000 | M14: food production | N14: 60a28926f7300b0001d31cac
A15: 14 | B15: DACH Industrial | C15: Lynn Proft | D15: Chief Procurement Officer | E15: Sandoz | F15: sandoz.com | G15: c_suite | I15: unavailable | J15: http://www.linkedin.com/in/lynn-de-proft | K15: Switzerland | L15: 23000 | M15: pharmaceuticals | N15: 687e94e38867970001fa8dd4
A16: 15 | B16: DACH Industrial | C16: Matteo Stefani | D16: Chief Procurement Officer - Head of Global Procurement | E16: Straumann Group | F16: straumann.com | G16: c_suite | I16: unavailable | J16: http://www.linkedin.com/in/matteostefani76 | K16: Switzerland | L16: 11000 | M16: medical devices | N16: 60ed6dd88166e90001e366d5
A17: 16 | B17: DACH Industrial | C17: Viktor Oberst | D17: Head of Purchasing | E17: ACO Group | F17: aco.com | G17: head | H17: viktor.oberst@aco.com | I17: verified | J17: http://www.linkedin.com/in/viktor-oberst-8506692b6 | K17: Bad Oldesloe, Germany | L17: 5500 | M17: architecture & planning | N17: 66bb0790d9dcad000106897e
A18: 17 | B18: DACH Industrial | C18: Stefan Schmidt | D18: Head of Purchasing | E18: BENTELER Group | F18: benteler.com | G18: head | H18: stefan.schmidt@benteler.com | I18: verified | J18: http://www.linkedin.com/in/stefan-schmidt-650ba1b8 | K18: Bielefeld, Germany | L18: 23000 | M18: automotive | N18: 60deab77cd462600012d0f62
A19: 18 | B19: DACH Industrial | C19: Vanessa Niederer | D19: Head of Purchasing | E19: Constantia Flexibles | F19: cflex.com | G19: head | H19: vanessa.niederer@cflex.com | I19: verified | J19: http://www.linkedin.com/in/vanessa-niederer-kudlacek-356a02153 | K19: Vienna, Austria | L19: 9600 | M19: packaging & containers | N19: 61388ef161b1e2000150bd95
A20: 19 | B20: DACH Industrial | C20: Daniel Azopardo | D20: Head of Procurement Indirect Materials & Services | E20: DAW SE | F20: daw.de | G20: head | I20: unavailable | J20: http://www.linkedin.com/in/daniel-miret-azopardo-88a6ab29 | K20: Seeheim-Jugenheim, Germany | L20: 6000 | M20: building materials | N20: 615077f6cf1a8e00018e77e7
A21: 20 | B21: DACH Industrial | C21: Ole Struve | D21: Head of Purchasing | E21: Dräger | F21: draeger.com | G21: head | H21: ole.struve@draeger.com | I21: verified | J21: http://www.linkedin.com/in/ole-struve-046b3234a | K21: Germany | L21: 17000 | M21: medical devices | N21: 6821a2add80d8b0001ba33dd
A22: 21 | B22: DACH Industrial | C22: Florian Noesterer | D22: Head of Purchasing | E22: ENGEL | F22: engelglobal.com | G22: head | H22: florian.noesterer@engel.at | I22: verified | J22: http://www.linkedin.com/in/florian-noesterer-a07381105 | K22: Austria | L22: 7000 | M22: machinery | N22: 60b3338990c70a000145f86f
A23: 22 | B23: DACH Industrial | C23: Jens Carrle | D23: Leiter Einkauf und Logistik | E23: ElringKlinger | F23: elringklinger.de | G23: head | H23: jens.carrle@elringklinger.com | I23: verified | J23: http://www.linkedin.com/in/jens-carrle-564276160 | K23: Germany | L23: 9100 | M23: automotive | N23: 60ba43e8dab34b00013985c4
A24: 23 | B24: DACH Industrial | C24: Sascha Horvath | D24: Head of Purchasing | E24: FORVIA HELLA | F24: hella.com | G24: head | H24: sascha.horvath@hella.com | I24: verified | J24: http://www.linkedin.com/in/sascha-horvath-597501181 | K24: Grosspetersdorf, Austria | L24: 37000 | M24: automotive | N24: 6024e156009d7c0001510b01
A25: 24 | B25: DACH Industrial | C25: Birger Diesem | D25: Head of Purchasing | E25: GMH Gruppe | F25: gmh-gruppe.de | G25: head | H25: birger.diesem@gmh-gruppe.de | I25: verified | J25: http://www.linkedin.com/in/birger-diesem-1a73b971 | K25: Bonn, Germany | L25: 6000 | M25: mining & metals | N25: 57dfa435a6da980b38c4b9de
A26: 25 | B26: DACH Industrial | C26: Andre Suter | D26: Head of Indirect Procurement | E26: Geberit | F26: geberit.com | G26: head | H26: andre.suter@geberit.com | I26: verified | J26: http://www.linkedin.com/in/andr%c3%a9-a-suter-a1a03647 | K26: Zuerich, Switzerland | L26: 12000 | M26: building materials | N26: 54a76e957468696de75d0a34
A27: 26 | B27: DACH Industrial | C27: Ilona Piekoszewska | D27: Global Head Indirect Procurement (Materials and Services) | E27: Givaudan | F27: givaudan.com | G27: head | H27: ilona.piekoszewska@givaudan.com | I27: verified | J27: http://www.linkedin.com/in/ilona-piekoszewska-mba-85057152 | K27: Pregny-Chambesy, Switzerland | L27: 18000 | M27: chemicals | N27: 60745c9ff8d4090001f62786
A28: 27 | B28: DACH Industrial | C28: Kati Bensch | D28: Head of Procurement Excellence | E28: HARTMANN GROUP | F28: hartmann.info | G28: head | H28: kati.bensch@hartmann.info | I28: verified | J28: http://www.linkedin.com/in/kati-bensch-18ab1b10 | K28: Ulm, Germany | L28: 11000 | M28: medical devices | N28: 66f9d7a583ba0c00016d6249
A29: 28 | B29: DACH Industrial | C29: Christian Lima-Wirth | D29: Head of Purchasing | E29: HOERBIGER | F29: hoerbiger.com | G29: head | H29: christian.lima-wirth@hoerbiger.com | I29: verified | J29: http://www.linkedin.com/in/christian-lima-wirth-00330b101 | K29: Vienna, Austria | L29: 6500 | M29: machinery | N29: 67cef6d7ea3a6b0001a2105d
A30: 29 | B30: DACH Industrial | C30: Markus Klein | D30: Leiter Einkauf Nichtproduktionsmaterial | E30: HYDAC Group | F30: hydac.com | G30: head | H30: markus.klein@hydac.com | I30: verified | J30: http://www.linkedin.com/in/markus-klein-612245a1 | K30: Germany | L30: 11000 | M30: machinery | N30: 57dd5f2ca6da987b3d3dc0a5
A31: 30 | B31: DACH Industrial | C31: Reinhard Pohl | D31: Leiter Einkauf Prozesse & Controlling | E31: Heraeus | F31: heraeus.com | G31: head | I31: unavailable | J31: http://www.linkedin.com/in/reinhard-pohl-08718497 | K31: Germany | L31: 16000 | M31: chemicals | N31: 54a732897468696b7fe61f1e
A32: 31 | B32: DACH Industrial | C32: Tobias Muehlens | D32: Head of Digital Procurement Tools & Processes @ Procurement Center of Competence | E32: Heraeus | F32: heraeus.com | G32: head | H32: tobias.muehlens@heraeus.com | I32: verified | J32: http://www.linkedin.com/in/tobiasmuehlens | K32: Hanau, Germany | L32: 16000 | M32: chemicals | N32: 6065715b1a18db0001965c63
A33: 32 | B33: DACH Industrial | C33: Gottfried Deuble | D33: Leiter Einkauf Deutschland | E33: Häfele SE & Co KG | F33: haefele.de | G33: head | H33: gottfried.deuble@haefele.de | I33: verified | J33: http://www.linkedin.com/in/gottfried-deuble-0222157 | K33: Wildberg, Germany | L33: 8000 | M33: furniture | N33: 54aa4331746869261b471200
A34: 33 | B34: DACH Industrial | C34: Florian Kraemer | D34: Head of Indirect Procurement & AI Procurement Lead | E34: Intersnack Group | F34: intersnackgroup.com | G34: head | H34: f.kraemer@intersnackgroup.com | I34: verified | J34: http://www.linkedin.com/in/florian-kr%c3%a4mer | K34: Duesseldorf, Germany | L34: 14000 | M34: food production | N34: 670653496ff1ff0001c8fe46
A35: 34 | B35: DACH Industrial | C35: Mara Hillermeier | D35: Head of Procurement Excellence Europe | E35: KOSTAL Group | F35: kostal.com | G35: head | H35: m.hillermeier@kostal.com | I35: verified | J35: http://www.linkedin.com/in/mara-hillermeier-6ab189112 | K35: Germany | L35: 21000 | M35: automotive | N35: 57d48018a6da9853c6d2c209
A36: 35 | B36: DACH Industrial | C36: Stefanie Schlitt | D36: Head of Indirect Procurement | E36: KSB Company | F36: ksb.com | G36: head | H36: stefanie.schlitt@ksb.com | I36: verified | J36: http://www.linkedin.com/in/stefanie-schlitt-52a4691b5 | K36: Kitzingen, Germany | L36: 9300 | M36: machinery | N36: 614d9220028cae0001c06ad3
A37: 36 | B37: DACH Industrial | C37: Karoline Strobl | D37: Head of Group Indirect Procurement | E37: KUKA | F37: kuka.com | G37: head | H37: karoline.strobl@kuka.com | I37: verified | J37: http://www.linkedin.com/in/karoline-strobl-94995538 | K37: Munich, Germany | L37: 16000 | M37: machinery | N37: 557132917369641423d10400
A38: 37 | B38: DACH Industrial | C38: Michael Proch | D38: Head of Indirect Category Management & Procurement Excellence (Global & EMEA) | E38: Knauf | F38: knauf.com | G38: head | H38: michael.proch@knauf.com | I38: verified | J38: http://www.linkedin.com/in/proch | K38: Wuerzburg, Germany | L38: 44000 | M38: building materials | N38: 66f8a5461fb6a7000101b5b8
A39: 38 | B39: DACH Industrial | C39: Udo Mayer | D39: Leiter Einkauf & Logistik | E39: Lenzing Group | F39: lenzing.com | G39: head | I39: unavailable | J39: http://www.linkedin.com/in/udo-mayer-1b903714 | K39: Frankfurt, Germany | L39: 8300 | M39: chemicals | N39: 54a753b1746869622040522a
A40: 39 | B40: DACH Industrial | C40: Herfried Holzer | D40: Strategic Procurement, Head of Indirect Purchasing | E40: Lohmann & Rauscher | F40: lohmann-rauscher.com | G40: head | H40: herfried.holzer@at.lrmed.com | I40: verified | J40: http://www.linkedin.com/in/herfried-holzer-b2993130a | K40: Vienna, Austria | L40: 5400 | M40: medical devices | N40: 6689cbd73dbef000018ec9cc
...

Sheet Companies
A1: # | B1: Segment | C1: Company | D1: Domain | E1: HQ | F1: Employees | G1: Revenue | H1: Industry | I1: Why it fits Lio's ICP
A2: 1 | B2: DACH Industrial | C2: TRUMPF | D2: trumpf.com | E2: Ditzingen, Germany | G2: 5.9B | H2: Machine tools / laser technology (NAICS 33324) | I2: Family-owned German Mittelstand machine-tool champion in the EUR 1-12B band
A3: 2 | B3: DACH Industrial | C3: Miele | D3: miele.com | E3: Guetersloh, Germany | G3: 6B | H3: Household appliances (NAICS 33522) | I3: Fourth-generation family-owned appliance manufacturer, conservative German enterprise IT
A4: 3 | B4: DACH Industrial | C4: Rohde & Schwarz | D4: rohde-schwarz.com | E4: Munich, Germany | G4: 3.7B | H4: Test & measurement / RF electronics (NAICS 33441) | I4: Family-owned Munich electronics group, same city and profile as Lio's reference base
A5: 4 | B5: DACH Industrial | C5: Dr. Oetker | D5: oetker.com | E5: Bielefeld, Germany | G5: 5B | H5: Food manufacturing (NAICS 311412) | I5: Classic family-owned German food group in the target revenue band
A6: 5 | B6: DACH Industrial | C6: Knorr-Bremse AG | D6: knorr-bremse.com | E6: Munich, Germany | G6: 9.2B | H6: Rail/commercial vehicle braking systems (NAICS 336510) | I6: Munich industrial with family-foundation anchor shareholder, EUR 9B revenue, SAP-heavy
A7: 6 | B7: DACH Industrial | C7: Giesecke+Devrient | D7: gi-de.com | E7: Munich, Germany | G7: 3.8B | H7: Security technology / banknote printing (NAICS 33911, 323111) | I7: Munich family-owned security-tech manufacturer, conservative enterprise estate
A8: 7 | B8: DACH Industrial | C8: Dräger | D8: draeger.com | E8: Luebeck, Germany | G8: 3.9B | H8: Medical & safety technology (NAICS 33911) | I8: Fifth-generation family-led medtech/safety manufacturer in band
A9: 8 | B9: DACH Industrial | C9: GEA Group | D9: gea.com | E9: Duesseldorf, Germany | G9: 6.4B | H9: Process engineering machinery (NAICS 333241) | I9: German process-machinery group, EUR 6.4B, classic SAP/Ariba estate
A10: 9 | B10: DACH Industrial | C10: KUKA | D10: kuka.com | E10: Augsburg, Germany | G10: 4.6B | H10: Robotics & automation (NAICS 333248) | I10: Bavarian robotics manufacturer in band; group indirect procurement lead surfaced in people search
A11: 10 | B11: DACH Industrial | C11: FORVIA HELLA | D11: hella.com | E11: Lippstadt, Germany | G11: 8.8B | H11: Automotive lighting & electronics (NAICS 33632) | I11: Founding-family-rooted German automotive supplier, EUR 8.8B
A12: 11 | B12: DACH Industrial | C12: MANN+HUMMEL | D12: mann-hummel.com | E12: Ludwigsburg, Germany | G12: 4.9B | H12: Filtration (NAICS 33911, 336390) | I12: Family-owned Swabian filtration leader; CPO and VP Procurement both surfaced
A13: 12 | B13: DACH Industrial | C13: Sartorius | D13: sartorius.com | E13: Goettingen, Germany | G13: 4.1B | H13: Lab & bioprocess equipment (NAICS 33324, 334516) | I13: German life-science equipment maker in band with complex direct/indirect spend
... A64: 63 | B64: US GBS & BPO Owners | C64: Microsoft | D64: microsoft.com | E64: Redmond, Washington, United States | G64: 331.8B | H64: Software / Cloud | I64: Mega-cap with huge indirect spend and mature GBS/outsourcing contracts to displace
A65: 64 | B65: US GBS & BPO Owners | C65: Google | D65: google.com | G65: 422.5B | H65: Internet / Technology | I65: Top-of-Fortune-500 scale indirect procurement and shared-services operations
A66: 65 | B66: US GBS & BPO Owners | C66: Apple | D66: apple.com | G66: 416.2B | H66: Consumer Electronics | I66: Largest-scale P2P volumes; enterprise procurement stack fits Lio's SAP/Ariba wedge
A67: 66 | B67: US GBS & BPO Owners | C67: Meta | D67: meta.com | G67: 201.0B | H67: Internet / Social Media | I67: Large US enterprise with centralized procurement ops and BPO-supported back office
A68: 67 | B68: US GBS & BPO Owners | C68: JPMorganChase | D68: jpmorganchase.com | G68: 279.7B | H68: Banking | I68: Massive shared-services and sourcing org; financial-services fit like Lio's Munich Re/ERGO base
A69: 68 | B69: US GBS & BPO Owners | C69: Citi | D69: citi.com | G69: 168.3B | H69: Banking | I69: Global GBS pioneer (two GBS/shared-services leaders surfaced in people search)
A70: 69 | B70: US GBS & BPO Owners | C70: Goldman Sachs | D70: goldmansachs.com | G70: 125.1B | H70: Investment Banking | I70: Large-enterprise financial services with heavy outsourced operations spend
A71: 70 | B71: US GBS & BPO Owners | C71: Mastercard | D71: mastercard.com | E71: Harrison, New York, United States | G71: 32.8B | H71: Payments | I71: F500 payments enterprise with global shared-services footprint
A72: 71 | B72: US GBS & BPO Owners | C72: Marsh | D72: marsh.com | E72: New York, New York, United States | G72: 27.0B | H72: Insurance Broking | I72: Insurance-sector fit (mirrors Lio's ERGO/Munich Re references) with large GBS org
A73: 72 | B73: US GBS & BPO Owners | C73: PepsiCo | D73: pepsico.com | G73: 93.9B | H73: Food & Beverage | I73: CPG giant with classic GBS/BPO-heavy procure-to-pay operations
A74: 73 | B74: US GBS & BPO Owners | C74: Procter & Gamble | D74: pg.com | G74: 87B | H74: Consumer Goods | I74: Invented the GBS model; prime target for agentic-BPO replacement pitch
A75: 74 | B75: US GBS & BPO Owners | C75: The Coca-Cola Company | D75: coca-cola.com | G75: 47.9B | H75: Beverages | I75: F500 CPG with outsourced finance/procurement shared services
A76: 75 | B76: US GBS & BPO Owners | C76: Mondelez International | D76: mondelezinternational.com | E76: Chicago, Illinois, United States | G76: 38.5B | H76: Food & Beverage | I76: Large GBS organization and heavy BPO contracts in P2P
A77: 76 | B77: US GBS & BPO Owners | C77: McCormick & Company | D77: mccormickcorporation.com | E77: Cockeysville, Maryland, United States | G77: 6.8B | H77: Food Manufacturing | I77: VP Head of GBS surfaced in people search; sized like Lio's Mittelstand-plus customers
A78: 77 | B78: US GBS & BPO Owners | C78: Cargill | D78: cargill.com | E78: Wayzata, Minnesota, United States | G78: 154B | H78: Agribusiness | I78: Largest US private company; sprawling shared-services and sourcing operations
A79: 78 | B79: US GBS & BPO Owners | C79: Bunge | D79: bunge.com | E79: Chesterfield, Missouri, United States | G79: 70.3B | H79: Agribusiness | I79: Global commodity trader with SAP-centric P2P at scale
A80: 79 | B80: US GBS & BPO Owners | C80: Pfizer | D80: pfizer.com | G80: 62.6B | H80: Pharmaceuticals | I80: VP GBS surfaced in people search; pharma sector mirrors Lio's Zeiss/Schaeffler industrial base
A81: 80 | B81: US GBS & BPO Owners | C81: Johnson & Johnson | D81: jnj.com | E81: New Brunswick, New Jersey, United States | G81: 94.2B | H81: Pharma / MedTech | I81: Major GBS operator (DePuy Synthes GBS head also surfaced) with large BPO contracts
A82: 81 | B82: US GBS & BPO Owners | C82: Tesla | D82: tesla.com | E82: Austin, Texas, United States | G82: 94.8B | H82: Automotive | I82: Automotive/manufacturing fit matching Lio's Brose/Schaeffler references
A83: 82 | B83: US GBS & BPO Owners | C83: Dell Technologies | D83: dell.com | G83: 113.5B | H83: IT Hardware | I83: VP Indirect Procurement surfaced in people search; enormous indirect-spend org
A84: 83 | B84: US GBS & BPO Owners | C84: Cisco | D84: cisco.com | E84: San Jose, California, United States | G84: 56.7B | H84: Networking / Technology | I84: Large enterprise with mature source-to-pay and GBS functions
A85: 84 | B85: US GBS & BPO Owners | C85: Oracle | D85: oracle.com | G85: 67.4B | H85: Enterprise Software | I85: F500-scale procurement ops; large shared-services organization
A86: 85 | B86: US GBS & BPO Owners | C86: Salesforce | D86: salesforce.com | G86: 41.5B | H86: Enterprise Software | I86: VP Procurement Operations surfaced in people search; large indirect-spend buyer
A87: 86 | B87: US GBS & BPO Owners | C87: Adobe | D87: adobe.com | G87: 23.8B | H87: Software | I87: Large US enterprise buyer with centralized procurement operations
A88: 87 | B88: US GBS & BPO Owners | C88: LinkedIn | D88: linkedin.com | E88: Sunnyvale, California, United States | G88: 17.8B | H88: Internet / Professional Network | I88: Enterprise-scale shared services within the Microsoft family
A89: 88 | B89: US GBS & BPO Owners | C89: Netflix | D89: netflix.com | G89: 45.2B | H89: Media / Streaming | I89: F500 media enterprise with growing procurement-operations maturity
A90: 89 | B90: US GBS & BPO Owners | C90: The Walt Disney Company | D90: thewaltdisneycompany.com | G90: 97.3B | H90: Media & Entertainment | I90: Massive shared-services and outsourced back-office spend
...

Sheet Approach Playbook
A1: Segment | B1: Buying center (who signs, who champions) | C1: Lead message | D1: Channel sequence | E1: Best rooms (from the event program) | F1: Proof points to lead with | G1: Timing triggers
A2: DACH Industrial (60 contacts / 851 in Apollo) | B2: CPO sponsors; COO/CFO is the economic buyer via the BPO/FTE line; Head of Procurement Excellence champions; CIO/CISO gatekeeps (ISO 27001 yes, SOC 2 not yet). | C2: Overlay, don't replace: agents operate your existing SAP/Ariba estate; 85% less manual work; ~120-FTE case at a Tier-1 manufacturer (EUR 7-9M/yr). | D2: Warm room first (BME/Handelsblatt/eLoesungstage), then German-language email + LinkedIn from a founder or AE, then Principals dinner invite. Cold email is the last resort in this culture, not the first. | E2: BME-Symposium Berlin (Nov 18-19) - SSOW DACH Berlin (Nov 17-19) - eLoesungstage (May 11-12, 2027) - Procurement Summit Hamburg (Jun 23-24, 2027) - Bots & Buyers EU (Oct 27-28) | F2: Schaeffler co-development MOU + COO quote; REHAU BME award + Porsche Consulting AI Impact Award 2026; 2-week integration. | G2: SAP/Ariba renewal windows; works-council-friendly re-roling narrative; family-owner conviction cycles (Maschinenbau-Gipfel attendance).
A3: Insurance & FS (40 contacts / 156 in Apollo) | B3: Head of Procurement / Sourcing & Vendor Management; compliance and audit functions in the room from day one. | C3: 100% indirect spend = the fastest agentic-BPO math in the portfolio; auditable 24/7 agents vs BPO black box, at ~7% of BPO cost. | D3: Reference-led: Munich Re "Agent Experience World" visit as the social proof; invite to a Lio office demo; then email the CPO office directly. | E3: DPW Amsterdam (Sep 30-Oct 1) - SSOW DACH Berlin (Nov 17-19) - Handelsblatt CPO Summit (Apr 6-7, 2027) | F3: Munich Re engagement (~30 procurement leaders through Lio's Munich showroom); ERGO instance live (ergo.asklio.ai); ISO 27001 + EU hosting. | G3: BPO/SSC contract renewals; DORA/outsourcing-audit pressure; year-end cost programs.
A4: US GBS & BPO Owners (60 contacts / 895 in Apollo) | B4: VP/Head of GBS, Shared Services, P2P/S2P GPOs - the people who SIGN outsourcing renewals. CPO is an ally, CFO decides. | C4: Your BPO costs 93% too much: same scope, ~7% of cost, 99.6% automation at 12 months, auditable, and you own the execution layer. | D4: Email-first (US norm) with the BPO-cost wedge, then SSOW/SIG room meetings booked around renewal windows; Petras (ex-Walmart) as sender/closer. | E4: SSON San Diego (Sep 14-17) - ProcureCon East Boston (Sep 28-30) - SIG Chicago (Oct 25-28) - SSOW Orlando (Mar 8-11, 2027) - Bots & Buyers NYC (Sep 23) | F4: Fortune-scale retail case (99.8% accuracy in 2 weeks, ~7% of BPO cost); Walmart engagement story via Petras; a16z backing. | G4: BPO contract renewal cycles (ask directly in sequence); GBS transformation mandates; "agentic AI" board directives.
A5: Utilities & Mobility (59 contacts / 343 in Apollo) | B5: Leiter Einkauf/Beschaffung + digitalization leads; works councils early; public-sector procurement rules at the Stadtwerke end. | C5: Regulated-grade autonomy: human-on-the-loop supervision, full audit trail, EU hosting - agents that pass an auditor's review. | D5: German-language webinar -> Bots & Buyers invite -> pilot proposal. Slow trust curve; do not lead with cold calls. | E5: BME circuit + SSOW DACH Berlin; Bots & Buyers EU (Deutsche Bahn, Lufthansa, SWM already in that room) | F5: Deutsche Bahn "Loom" pilot; DB/Lufthansa/SWM attendance at Bots & Buyers Clubhouse; TUEV SUED knowledge-base testimonial. | G5: Energy-cost pressure programs; digitalization budgets; Konzern efficiency programs.
